INFO 2024-08-23 13:24:26,994 autoreload Watching for file changes with StatReloader
WARNING 2024-08-23 13:25:21,996 log Bad Request: /generate-report/
WARNING 2024-08-23 13:25:21,998 basehttp "GET /generate-report/ HTTP/1.1" 400 21
WARNING 2024-08-23 13:25:22,044 log Bad Request: /favicon.ico
WARNING 2024-08-23 13:25:22,044 basehttp "GET /favicon.ico HTTP/1.1" 400 21
ERROR 2024-08-23 13:25:37,152 log Internal Server Error: /generate-report/
Traceback (most recent call last):
  File "C:\Users\Adarsh\AppData\Local\Programs\Python\Python311\Lib\site-packages\django\db\backends\utils.py", line 89, in _execute
    return self.cursor.execute(sql, params)
           ^^^^^^^^^^^^^^^^^^^^^^^^^^^^^^^^
psycopg2.errors.UndefinedColumn: column leads_report.tenant_id does not exist
LINE 1: ..._report"."revenue", "leads_report"."total_leads", "leads_rep...
                                                             ^


The above exception was the direct cause of the following exception:

Traceback (most recent call last):
  File "C:\Users\Adarsh\AppData\Local\Programs\Python\Python311\Lib\site-packages\django\core\handlers\exception.py", line 55, in inner
    response = get_response(request)
               ^^^^^^^^^^^^^^^^^^^^^
  File "C:\Users\Adarsh\AppData\Local\Programs\Python\Python311\Lib\site-packages\django\core\handlers\base.py", line 197, in _get_response
    response = wrapped_callback(request, *callback_args, **callback_kwargs)
               ^^^^^^^^^^^^^^^^^^^^^^^^^^^^^^^^^^^^^^^^^^^^^^^^^^^^^^^^^^^^
  File "C:\Users\Adarsh\MyProject\Deployed_Finals\django-crm\django_crm_backend\leads\views.py", line 121, in generate_and_get_report_view
    report = generate_or_get_report()
             ^^^^^^^^^^^^^^^^^^^^^^^^
  File "C:\Users\Adarsh\MyProject\Deployed_Finals\django-crm\django_crm_backend\leads\views.py", line 94, in generate_or_get_report
    report_today = Report.objects.filter(created_at__date=today).first()
                   ^^^^^^^^^^^^^^^^^^^^^^^^^^^^^^^^^^^^^^^^^^^^^^^^^^^^^
  File "C:\Users\Adarsh\AppData\Local\Programs\Python\Python311\Lib\site-packages\django\db\models\query.py", line 1046, in first
    for obj in (self if self.ordered else self.order_by("pk"))[:1]:
  File "C:\Users\Adarsh\AppData\Local\Programs\Python\Python311\Lib\site-packages\django\db\models\query.py", line 394, in __iter__
    self._fetch_all()
  File "C:\Users\Adarsh\AppData\Local\Programs\Python\Python311\Lib\site-packages\django\db\models\query.py", line 1866, in _fetch_all
    self._result_cache = list(self._iterable_class(self))
                         ^^^^^^^^^^^^^^^^^^^^^^^^^^^^^^^^
  File "C:\Users\Adarsh\AppData\Local\Programs\Python\Python311\Lib\site-packages\django\db\models\query.py", line 87, in __iter__
    results = compiler.execute_sql(
              ^^^^^^^^^^^^^^^^^^^^^
  File "C:\Users\Adarsh\AppData\Local\Programs\Python\Python311\Lib\site-packages\django\db\models\sql\compiler.py", line 1395, in execute_sql
    cursor.execute(sql, params)
  File "C:\Users\Adarsh\AppData\Local\Programs\Python\Python311\Lib\site-packages\django\db\backends\utils.py", line 103, in execute
    return super().execute(sql, params)
           ^^^^^^^^^^^^^^^^^^^^^^^^^^^^
  File "C:\Users\Adarsh\AppData\Local\Programs\Python\Python311\Lib\site-packages\django\db\backends\utils.py", line 67, in execute
    return self._execute_with_wrappers(
           ^^^^^^^^^^^^^^^^^^^^^^^^^^^^
  File "C:\Users\Adarsh\AppData\Local\Programs\Python\Python311\Lib\site-packages\django\db\backends\utils.py", line 80, in _execute_with_wrappers
    return executor(sql, params, many, context)
           ^^^^^^^^^^^^^^^^^^^^^^^^^^^^^^^^^^^^
  File "C:\Users\Adarsh\AppData\Local\Programs\Python\Python311\Lib\site-packages\django\db\backends\utils.py", line 84, in _execute
    with self.db.wrap_database_errors:
  File "C:\Users\Adarsh\AppData\Local\Programs\Python\Python311\Lib\site-packages\django\db\utils.py", line 91, in __exit__
    raise dj_exc_value.with_traceback(traceback) from exc_value
  File "C:\Users\Adarsh\AppData\Local\Programs\Python\Python311\Lib\site-packages\django\db\backends\utils.py", line 89, in _execute
    return self.cursor.execute(sql, params)
           ^^^^^^^^^^^^^^^^^^^^^^^^^^^^^^^^
django.db.utils.ProgrammingError: column leads_report.tenant_id does not exist
LINE 1: ..._report"."revenue", "leads_report"."total_leads", "leads_rep...
                                                             ^

ERROR 2024-08-23 13:25:37,156 basehttp "GET /generate-report/ HTTP/1.1" 500 132352
INFO 2024-08-23 13:27:02,320 basehttp "OPTIONS /fetch-all-emails HTTP/1.1" 200 0
WARNING 2024-08-23 13:27:06,240 log Not Found: /fetch-all-emails
WARNING 2024-08-23 13:27:06,240 basehttp "GET /fetch-all-emails HTTP/1.1" 404 16301
WARNING 2024-08-23 13:58:02,453 log Not Found: /fetch-all-emails
WARNING 2024-08-23 13:58:02,457 basehttp "GET /fetch-all-emails HTTP/1.1" 404 16301
INFO 2024-08-23 14:49:53,162 autoreload C:\Users\Adarsh\MyProject\Deployed_Finals\django-crm\django_crm_backend\leads\models.py changed, reloading.
INFO 2024-08-23 14:49:57,614 autoreload Watching for file changes with StatReloader
INFO 2024-08-23 14:50:35,711 basehttp "GET /generate-report/ HTTP/1.1" 200 93
